Traceback (most recent call last):
  File "/home/runner/miniconda3/envs/instrument-cookbooks-dev/lib/python3.10/site-packages/jupyter_cache/executors/utils.py", line 58, in single_nb_execution
    executenb(
  File "/home/runner/miniconda3/envs/instrument-cookbooks-dev/lib/python3.10/site-packages/nbclient/client.py", line 1319, in execute
    return NotebookClient(nb=nb, resources=resources, km=km, **kwargs).execute()
  File "/home/runner/miniconda3/envs/instrument-cookbooks-dev/lib/python3.10/site-packages/jupyter_core/utils/__init__.py", line 165, in wrapped
    return loop.run_until_complete(inner)
  File "/home/runner/miniconda3/envs/instrument-cookbooks-dev/lib/python3.10/asyncio/base_events.py", line 649, in run_until_complete
    return future.result()
  File "/home/runner/miniconda3/envs/instrument-cookbooks-dev/lib/python3.10/site-packages/nbclient/client.py", line 709, in async_execute
    await self.async_execute_cell(
  File "/home/runner/miniconda3/envs/instrument-cookbooks-dev/lib/python3.10/site-packages/nbclient/client.py", line 1062, in async_execute_cell
    await self._check_raise_for_error(cell, cell_index, exec_reply)
  File "/home/runner/miniconda3/envs/instrument-cookbooks-dev/lib/python3.10/site-packages/nbclient/client.py", line 918, in _check_raise_for_error
    raise CellExecutionError.from_cell_and_msg(cell, exec_reply_content)
nbclient.exceptions.CellExecutionError: An error occurred while executing the following cell:
------------------
ds = xr.open_dataset(files[-1])
------------------


[0;31m---------------------------------------------------------------------------[0m
[0;31mIndexError[0m                                Traceback (most recent call last)
Cell [0;32mIn[4], line 1[0m
[0;32m----> 1[0m ds [38;5;241m=[39m xr[38;5;241m.[39mopen_dataset([43mfiles[49m[43m[[49m[38;5;241;43m-[39;49m[38;5;241;43m1[39;49m[43m][49m)

[0;31mIndexError[0m: list index out of range

